#VRML_SIM R2023b utf8

EXTERNPROTO "https://raw.githubusercontent.com/cyberbotics/webots/R2023b/projects/objects/backgrounds/protos/TexturedBackground.proto"
EXTERNPROTO "https://raw.githubusercontent.com/cyberbotics/webots/R2023b/projects/objects/backgrounds/protos/TexturedBackgroundLight.proto"
EXTERNPROTO "../protos/RectangleArenaThree.proto"
EXTERNPROTO "https://raw.githubusercontent.com/cyberbotics/webots/R2023b/projects/appearances/protos/Parquetry.proto"
EXTERNPROTO "../protos/WoodenChair.proto"

WorldInfo {
  info [
    "Example use of a Pen device on paper."
  ]
  title "Pen"
}
Viewpoint {
  orientation 0.25479870103525404 -0.3281953548729565 -0.9095963011086629 5.209254312214615
  position -4.869525209599893 -7.7327318058209915 3.972065515944988
}
TexturedBackground {
}
TexturedBackgroundLight {
}
RectangleArenaThree {
  floorSize 3.5 3.5
  floorTileSize 1 1
  floorAppearance Parquetry {
    type "light strip"
  }
}
DEF MyBot Robot {
  translation 0 -0.15 0
  rotation 0 0 1 -2.141595
  children [
    Pose {
      translation 0 0 0.0415
      rotation 0 0 1 -1.570796
      children [
        Shape {
          appearance PBRAppearance {
            baseColor 0.0820075 0.364731 0.8
            roughness 1
            metalness 0
          }
          geometry DEF BODY Cylinder {
            height 0.08
            radius 0.045
          }
        }
      ]
    }
    HingeJoint {
      jointParameters HingeJointParameters {
        axis 0 1 0
        anchor 0 0 0.025
      }
      device [
        RotationalMotor {
          name "left wheel motor"
          consumptionFactor 70
          maxVelocity 15
        }
        PositionSensor {
          name "left wheel sensor"
        }
      ]
      endPoint Solid {
        translation 0 0.045 0.025
        rotation 0.1344869543855967 -0.1344869543855967 -0.9817466670176033 1.589217
        children [
          DEF WHEEL Pose {
            rotation 0.577656895078166 0.5771968951617173 -0.5771968951617173 -2.093935
            children [
              Shape {
                appearance PBRAppearance {
                  baseColor 1 0 0
                  roughness 1
                  metalness 0
                }
                geometry Cylinder {
                  height 0.01
                  radius 0.025
                }
              }
            ]
          }
        ]
        name "left wheel"
        boundingObject USE WHEEL
        physics DEF PHYSICS_WHEEL Physics {
          density -1
          mass 0.05
        }
      }
    }
    HingeJoint {
      jointParameters HingeJointParameters {
        axis 0 1 0
        anchor 0 0 0.025
      }
      device [
        RotationalMotor {
          name "right wheel motor"
          consumptionFactor 70
          maxVelocity 15
        }
        PositionSensor {
          name "right wheel sensor"
        }
      ]
      endPoint Solid {
        translation 0 -0.045 0.025
        rotation -0.06235700094427207 0.06235700094427207 -0.9961040150840031 1.5746999999999995
        children [
          USE WHEEL
        ]
        name "right wheel"
        boundingObject USE WHEEL
        physics USE PHYSICS_WHEEL
      }
    }
    Pen {
      translation 0 0 0.001
      children [
        Pose {
          translation 0 0 0.07
          children [
            Shape {
              appearance PBRAppearance {
                baseColor 1 0.692371 0
                roughness 0.3707939685999999
                metalness 0
              }
              geometry Cylinder {
                height 0.14
                radius 0.004
              }
            }
          ]
        }
      ]
      inkDensity 1
      leadSize 0.004
    }
  ]
  name "MyBot"
  boundingObject Pose {
    translation 0 0 0.0415
    rotation 0 0 1 -1.570796
    children [
      USE BODY
    ]
  }
  physics Physics {
    density -1
    mass 0.5
    centerOfMass [
      0 0 0
    ]
  }
  controller "supervisor_without_trail"
  supervisor TRUE
}
WoodenChair {
  translation 0.852276 -1.66547 0.278137
  rotation -0.09315450837457903 0.7004670629719042 0.7075790636112722 -2.9576903061004254
}
Solid {
  children [
    DEF PAPER Shape {
      appearance PBRAppearance {
        roughness 1
        metalness 0
      }
      geometry Box {
        size 2 2 0.001
      }
    }
  ]
  name "paper"
  boundingObject USE PAPER
}